Workbook

Sheet Resumen
A1: RESUMEN FINANCIERO ECO STRUCT
A3: DATOS GENERALES
A4: Total Certificaciones: | B4: ='Certificaciones'!C24
A5: Total Gastos Generales: | B5: ='Gastos Generales'!E566
A6: Total Vehiculos: | B6: ='Vehiculos'!E35
A7: Total Gastos Comunes: | B7: =B5+B6
A8: Total Mano de Obra: | B8: ='Mano de Obra'!D30
A10: DESGLLOSE POR PROYECTO (con Prorrateo)
A11: Proyecto | B11: Certificacion (EUR) | C11: % Certif. | D11: Gastos Prorrateados (EUR) | E11: Gastos Directos (EUR) | F11: Mano de Obra (EUR) | G11: TOTAL COSTE (EUR) | H11: Margen (EUR) | I11: % Coste/Certif.
A12: ='Certificaciones'!B4 | B12: ='Certificaciones'!C4 | C12: ='Certificaciones'!D4 | D12: =C12*$B$7 | E12: =SUMIF('Gastos por Proyecto'!A:A,A12,'Gastos por Proyecto'!B:B) | F12: =SUMIF('Mano de Obra'!A:A,A12,'Mano de Obra'!D:D) | G12: =D12+E12+F12 | H12: =B12-G12 | I12: =IF(B12=0,0,G12/B12)
A13: ='Certificaciones'!B5 | B13: ='Certificaciones'!C5 | C13: ='Certificaciones'!D5 | D13: =C13*$B$7 | E13: =SUMIF('Gastos por Proyecto'!A:A,A13,'Gastos por Proyecto'!B:B) | F13: =SUMIF('Mano de Obra'!A:A,A13,'Mano de Obra'!D:D) | G13: =D13+E13+F13 | H13: =B13-G13 | I13: =IF(B13=0,0,G13/B13)
A14: ='Certificaciones'!B6 | B14: ='Certificaciones'!C6 | C14: ='Certificaciones'!D6 | D14: =C14*$B$7 | E14: =SUMIF('Gastos por Proyecto'!A:A,A14,'Gastos por Proyecto'!B:B) | F14: =SUMIF('Mano de Obra'!A:A,A14,'Mano de Obra'!D:D) | G14: =D14+E14+F14 | H14: =B14-G14 | I14: =IF(B14=0,0,G14/B14)
A15: ='Certificaciones'!B7 | B15: ='Certificaciones'!C7 | C15: ='Certificaciones'!D7 | D15: =C15*$B$7 | E15: =SUMIF('Gastos por Proyecto'!A:A,A15,'Gastos por Proyecto'!B:B) | F15: =SUMIF('Mano de Obra'!A:A,A15,'Mano de Obra'!D:D) | G15: =D15+E15+F15 | H15: =B15-G15 | I15: =IF(B15=0,0,G15/B15)
A16: ='Certificaciones'!B8 | B16: ='Certificaciones'!C8 | C16: ='Certificaciones'!D8 | D16: =C16*$B$7 | E16: =SUMIF('Gastos por Proyecto'!A:A,A16,'Gastos por Proyecto'!B:B) | F16: =SUMIF('Mano de Obra'!A:A,A16,'Mano de Obra'!D:D) | G16: =D16+E16+F16 | H16: =B16-G16 | I16: =IF(B16=0,0,G16/B16)
A17: ='Certificaciones'!B9 | B17: ='Certificaciones'!C9 | C17: ='Certificaciones'!D9 | D17: =C17*$B$7 | E17: =SUMIF('Gastos por Proyecto'!A:A,A17,'Gastos por Proyecto'!B:B) | F17: =SUMIF('Mano de Obra'!A:A,A17,'Mano de Obra'!D:D) | G17: =D17+E17+F17 | H17: =B17-G17 | I17: =IF(B17=0,0,G17/B17)
A18: ='Certificaciones'!B10 | B18: ='Certificaciones'!C10 | C18: ='Certificaciones'!D10 | D18: =C18*$B$7 | E18: =SUMIF('Gastos por Proyecto'!A:A,A18,'Gastos por Proyecto'!B:B) | F18: =SUMIF('Mano de Obra'!A:A,A18,'Mano de Obra'!D:D) | G18: =D18+E18+F18 | H18: =B18-G18 | I18: =IF(B18=0,0,G18/B18)
A19: ='Certificaciones'!B11 | B19: ='Certificaciones'!C11 | C19: ='Certificaciones'!D11 | D19: =C19*$B$7 | E19: =SUMIF('Gastos por Proyecto'!A:A,A19,'Gastos por Proyecto'!B:B) | F19: =SUMIF('Mano de Obra'!A:A,A19,'Mano de Obra'!D:D) | G19: =D19+E19+F19 | H19: =B19-G19 | I19: =IF(B19=0,0,G19/B19)
A20: ='Certificaciones'!B12 | B20: ='Certificaciones'!C12 | C20: ='Certificaciones'!D12 | D20: =C20*$B$7 | E20: =SUMIF('Gastos por Proyecto'!A:A,A20,'Gastos por Proyecto'!B:B) | F20: =SUMIF('Mano de Obra'!A:A,A20,'Mano de Obra'!D:D) | G20: =D20+E20+F20 | H20: =B20-G20 | I20: =IF(B20=0,0,G20/B20)
A21: ='Certificaciones'!B13 | B21: ='Certificaciones'!C13 | C21: ='Certificaciones'!D13 | D21: =C21*$B$7 | E21: =SUMIF('Gastos por Proyecto'!A:A,A21,'Gastos por Proyecto'!B:B) | F21: =SUMIF('Mano de Obra'!A:A,A21,'Mano de Obra'!D:D) | G21: =D21+E21+F21 | H21: =B21-G21 | I21: =IF(B21=0,0,G21/B21)
A22: ='Certificaciones'!B14 | B22: ='Certificaciones'!C14 | C22: ='Certificaciones'!D14 | D22: =C22*$B$7 | E22: =SUMIF('Gastos por Proyecto'!A:A,A22,'Gastos por Proyecto'!B:B) | F22: =SUMIF('Mano de Obra'!A:A,A22,'Mano de Obra'!D:D) | G22: =D22+E22+F22 | H22: =B22-G22 | I22: =IF(B22=0,0,G22/B22)
A23: ='Certificaciones'!B15 | B23: ='Certificaciones'!C15 | C23: ='Certificaciones'!D15 | D23: =C23*$B$7 | E23: =SUMIF('Gastos por Proyecto'!A:A,A23,'Gastos por Proyecto'!B:B) | F23: =SUMIF('Mano de Obra'!A:A,A23,'Mano de Obra'!D:D) | G23: =D23+E23+F23 | H23: =B23-G23 | I23: =IF(B23=0,0,G23/B23)
... A31: ='Certificaciones'!B23 | B31: ='Certificaciones'!C23 | C31: ='Certificaciones'!D23 | D31: =C31*$B$7 | E31: =SUMIF('Gastos por Proyecto'!A:A,A31,'Gastos por Proyecto'!B:B) | F31: =SUMIF('Mano de Obra'!A:A,A31,'Mano de Obra'!D:D) | G31: =D31+E31+F31 | H31: =B31-G31 | I31: =IF(B31=0,0,G31/B31)
A32: TOTAL GENERAL | B32: =SUM(B12:B31) | C32: =SUM(C12:C31) | D32: =SUM(D12:D31) | E32: =SUM(E12:E31) | F32: =SUM(F12:F31) | G32: =SUM(G12:G31) | H32: =SUM(H12:H31) | I32: =IF(B32=0,0,G32/B32)

Sheet Certificaciones
A1: CERTIFICACIONES A FECHA DE 31/08/2026
A3: N | B3: Proyecto | C3: Certificacion (EUR) | D3: % del Total | E3: Observaciones
A4: 1 | B4: FORMENTERA 14, JUANMA | C4: 451635.85 | D4: =C4/C24
A5: 2 | B5: FORMENTERA 12, JOAQUIN | C5: 363068.33 | D5: =C5/C24
A6: 3 | B6: PLAZA CIRCULAR | C6: 278129.21 | D6: =C6/C24
A7: 4 | B7: LA ALBERCA | C7: 116432.26 | D7: =C7/C24
A8: 5 | B8: OBRA LUC2 | C8: 88834.71 | D8: =C8/C24
A9: 6 | B9: EDIFICIO ALICANTE C/MAESTRO BARBIERI (LA PARTE DIFICIL) | C9: 63277.34 | D9: =C9/C24 | E9: 24014
A10: 7 | B10: CUARTEL DE ARTILLERIA, MURCIA (LA PARTE DIFICIL) | C10: 3288 | D10: =C10/C24 | E10: 24015
A11: 8 | B11: CEMENTERIO, MURCIA | C11: 46635.25 | D11: =C11/C24
A12: 9 | B12: BARINAS | C12: 45611.44 | D12: =C12/C24
A13: 10 | B13: HELENA Y JACOBO | C13: 41569.41 | D13: =C13/C24
A14: 11 | B14: SANTA ROSA | C14: 23917.62 | D14: =C14/C24
A15: 12 | B15: CASTILLO DE ELDA | C15: 21606.67 | D15: =C15/C24
A16: 13 | B16: A-13 | C16: 16241.92 | D16: =C16/C24
A17: 14 | B17: CARLA, PINOSO | C17: 15050.98 | D17: =C17/C24
A18: 15 | B18: CARTAGENA, MURCIA | C18: 13330.32 | D18: =C18/C24
A19: 16 | B19: GARAJE MURCIA | C19: 8875.66 | D19: =C19/C24
A20: 17 | B20: CBS | C20: 7600 | D20: =C20/C24
A21: 18 | B21: PISO IBI | C21: 4320 | D21: =C21/C24 | E21: Administracion
A22: 19 | B22: PEREAMAR | C22: 2073.34 | D22: =C22/C24
A23: 20 | B23: PADRE TRINI | C23: 1407.99 | D23: =C23/C24
B24: TOTAL CERTIFICACIONES | C24: =SUM(C4:C23) | D24: =SUM(D4:D23)

Sheet Gastos Generales
A1: GASTOS GENERALES (562 facturas)
A3: Codigo | B3: Fecha | C3: Titulo/Concepto | D3: Proveedor | E3: Importe (EUR) | F3: Observaciones
A4: 1.897,00 | B4: 01/09/2026 | C4: PLENOIL JULIO | D4: PLENOIL SL. | E4: 1699.09
A5: 1.882,00 | B5: 26/08/2026 | C5: ASESORIA LABORAL JULIO | E5: 260
A6: 1.875,00 | B6: 26/08/2026 | C6: REPOSTAJE | D6: CONCORDY SA | E6: 74.39
A7: 1.874,00 | B7: 26/08/2026 | C7: RECONOCIMIENTOS MEDICOS | D7: EUROPREVEN SERVICIOS DE PREVENCION DE RIESGOS LABORALES SL | E7: 175.8
A8: 1.873,00 | B8: 26/08/2026 | C8: ASESORAMIENTO CONTABLE FISCAL | E8: 360.15
A9: 1.860,00 | B9: 28/07/2026 | C9: GRUA | D9: GRUAS Y MAQUINARIA PETREL SL | E9: 260
A10: 1.850,00 | B10: 24/07/2026 | C10: CUERDA | D10: FERRELDA SL | E10: 64.7
A11: 1.846,00 | B11: 24/07/2026 | C11: LAVADO COHES | D11: FARES JAVIER HERNANDEZ OSORIO | E11: 59
A12: 1.845,00 | B12: 24/07/2026 | C12: LAVADO OPEL COMBO | D12: FARES JAVIER HERNANDEZ OSORIO | E12: 35
A13: 1.842,00 | B13: 24/07/2026 | C13: SACO ASPIRADORA | D13: HILTI ESPAÑOLA SA | E13: 74.76
A14: 1.827,00 | B14: 21/07/2026 | C14: REPOSTAJE | D14: REPSOL SOLUCIONES ENERGETICAS SA. | E14: 16.53
A15: 1.826,00 | B15: 21/07/2026 | C15: ALQUILER NAVE JULIO | D15: PINKY VELVET INTERNATIONAL SL | E15: 350
A16: 1.825,00 | B16: 21/07/2026 | C16: REPOSTAJE | D16: CAMPSA ESTACIONES DE SERVICIO SA | E16: 22.97
A17: 1.822,00 | B17: 21/07/2026 | C17: DISCO DE CORTE | D17: JUAN JOSÉ MUÑOZ ROBLES | E17: 187.5
A18: 1.815,00 | B18: 14/07/2026 | C18: SPRAY PINTURA | D18: PINTURAS IDELLA SL. | E18: 19.31
A19: 1.814,00 | B19: 14/07/2026 | C19: RECONOCIMIENTO MÉDICO | D19: EUROPREVEN SERVICIOS DE PREVENCION DE RIESGOS LABORALES SL | E19: 175.8
A20: 1.811,00 | B20: 13/07/2026 | C20: ASESORÍA LABORAL JUNIO | E20: 260
A21: 1.808,00 | B21: 10/07/2026 | C21: TAPA POROS HIERRO GALVANIZADO | D21: SUMINISTROS DOMINGUEZ AGUILERA ELDA SL. | E21: -17
A22: 1.807,00 | B22: 10/07/2026 | C22: FONTANERIA | D22: SUMINISTROS DOMINGUEZ AGUILERA ELDA SL. | E22: -29.68
A23: 1.806,00 | B23: 10/07/2026 | C23: MAQUINARIA HONDA | D23: POLI PRIMI SL | E23: 1983.47
A24: 1.805,00 | B24: 10/07/2026 | C24: HOLDED JUNIO | D24: HOLDED TECHNOLOGIES SL. | E24: 59
A25: 1.799,00 | B25: 10/07/2026 | C25: PLENOIL JUNIO | D25: PLENOIL SL. | E25: 1745.38
A26: 1.797,00 | B26: 10/07/2026 | C26: VARIOS COMPRA | D26: CASH LEVANTE SL | E26: 134.86
A27: 1.794,00 | B27: 10/07/2026 | C27: NATURGY JUNIO | E27: 30.35
A28: 1.786,00 | B28: 09/07/2026 | C28: SACO PARA POLVO | D28: HILTI ESPAÑOLA SA | E28: 100.28
A29: 1.785,00 | B29: 09/07/2026 | C29: REPOSTAJE | D29: JR VIDAL RICO SL | E29: 65.69
A30: 1.776,00 | B30: 02/07/2026 | C30: MATERIAL | D30: SUMINISTROS DOMINGUEZ AGUILERA ELDA SL. | E30: 11.83
A31: 1.775,00 | B31: 02/07/2026 | C31: ARANDELAS | D31: SUMINISTROS DOMINGUEZ AGUILERA ELDA SL. | E31: 43.75
A32: 1.774,00 | B32: 02/07/2026 | C32: FONTANERIA | D32: SUMINISTROS DOMINGUEZ AGUILERA ELDA SL. | E32: 29.68
A33: 1.768,00 | B33: 02/07/2026 | C33: CONTROLADOR PH | D33: SUMINISTROS DOMINGUEZ AGUILERA ELDA SL. | E33: 34.83
A34: 1.767,00 | B34: 01/07/2026 | C34: MATERIAL OFICINA | D34: LOPA PAPER SL. | E34: 88.1
A35: 1.766,00 | B35: 30/06/2026 | C35: VIA T | E35: 2.69
A36: 1.756,00 | B36: 26/06/2026 | C36: REPOSTAJE | D36: EXPLOTACION ESTACION DE SERVICIO SA | E36: 72.16
A37: 1.755,00 | B37: 26/06/2026 | C37: VARIOS | D37: DM BRICO SL | E37: 218.18
A38: 1.754,00 | B38: 26/06/2026 | C38: FOCOS LUZ | D38: LEROY MERLIN ESPAÑA SL | E38: 66.07
A39: 1.753,00 | B39: 26/06/2026 | C39: PH REDUCTOR | D39: LEROY MERLIN ESPAÑA SL | E39: 19.48
A40: 1.752,00 | B40: 26/06/2026 | C40: RUEDAS | D40: FERRELDA SL | E40: 20.38
A41: 1.751,00 | B41: 26/06/2026 | C41: ROPA LABORAL / BERMUDAS | D41: FORMATO DIGITAL ACTIVIDADES PUBLICITARIAS SOCIEDAD LIMITADA. | E41: 142.6
...

Sheet Vehiculos
A1: GASTOS DE VEHICULOS (31 facturas)
A3: Codigo | B3: Fecha | C3: Titulo/Concepto | D3: Proveedor | E3: Importe (EUR) | F3: Observaciones
A4: 1.792,00 | B4: 10/07/2026 | C4: OPEL COMBO - CAMBIO RUEDAS | D4: AUTOCENTRO JIMENEZ ELDA SL | E4: 552.88
A5: 1.700,00 | B5: 12/06/2026 | C5: COMPRA RENAULT SCENIC | E5: 1000
A6: 1.660,00 | B6: 04/06/2026 | C6: REPARACIÓN COCHE | D6: AMADOR ALBERT CASCALES Y JOSE FRANCISCO ALBERTO CASCALES TALLERES ALBERT S.C. | E6: 235.24
A7: 1.439,00 | B7: 23/04/2026 | C7: PUESTA A PUNTO VEHÍCULO | D7: AMADOR ALBERT CASCALES Y JOSE FRANCISCO ALBERTO CASCALES TALLERES ALBERT S.C. | E7: 430.77
A8: 1.437,00 | B8: 23/04/2026 | C8: COMPRA CINTROEN C4 | E8: 1900
A9: 1.434,00 | B9: 23/04/2026 | C9: ITV CITROEN C4 | D9: SOCIETAT VALENCIANA D'INSPECCIO TECNICA DE VEHICLES SA. | E9: 47.13
A10: 1.426,00 | B10: 23/04/2026 | C10: HONORARIOS CAMBIO COCHE C4 | D10: ACCIONGEST ASEGEST SLP. | E10: 201.9
A11: 1.379,00 | B11: 23/04/2026 | C11: REPARACIÓN C4 | D11: AMADOR ALBERT CASCALES Y JOSE FRANCISCO ALBERTO CASCALES TALLERES ALBERT S.C. | E11: 513.41
A12: 1.377,00 | B12: 23/04/2026 | C12: REPARACIÓN COCHE | D12: AMADOR ALBERT CASCALES Y JOSE FRANCISCO ALBERTO CASCALES TALLERES ALBERT S.C. | E12: 884.84
A13: 1.376,00 | B13: 23/04/2026 | C13: PASSTILLAS DE FRENO | D13: AMADOR ALBERT CASCALES Y JOSE FRANCISCO ALBERTO CASCALES TALLERES ALBERT S.C. | E13: 224.06
A14: 1.370,00 | B14: 23/04/2026 | C14: REPARACIÓN VEHÍCULO | D14: AMADOR ALBERT CASCALES Y JOSE FRANCISCO ALBERTO CASCALES TALLERES ALBERT S.C. | E14: 450.74
A15: 1.356,00 | B15: 23/04/2026 | C15: REPARACIÓN VEHÍCULO | D15: AMADOR ALBERT CASCALES Y JOSE FRANCISCO ALBERTO CASCALES TALLERES ALBERT S.C. | E15: 605
A16: 1.308,00 | B16: 23/04/2026 | C16: REPARACIÓN | D16: AMADOR ALBERT CASCALES Y JOSE FRANCISCO ALBERTO CASCALES TALLERES ALBERT S.C. | E16: 74.15
A17: 1.220,00 | B17: 02/04/2026 | C17: PRE ITV CITROEN C4 | D17: AUTOCENTRO JIMENEZ ELDA SL | E17: 85
A18: 1.209,00 | B18: 08/04/2026 | C18: REPARACIÓN CITROEN C4 | D18: AMADOR ALBERT CASCALES Y JOSE FRANCISCO ALBERTO CASCALES TALLERES ALBERT S.C. | E18: 373.71
A19: 1.179,00 | B19: 31/03/2026 | C19: OPEL MOVANO | D19: Juan Abellán Lozano | E19: 394.64
A20: 1.098,00 | B20: 11/03/2026 | C20: OPEL MOVANO | D20: AUTOCENTRO JIMENEZ ELDA SL | E20: 296.87
... A34: 827,00 | B34: 20/02/2026 | C34: REPARACIÓN VEHICULO | D34: AUTOCENTRO JIMENEZ ELDA SL | E34: 677.44
C35: TOTAL VEHICULOS | E35: =SUM(E4:E34)

Sheet Mano de Obra
A1: GASTOS DE MANO DE OBRA
A2: Tarifa: 20 EUR/hora (configurable)
A4: Proyecto | B4: Horas | C4: Tarifa (EUR/h) | D4: Total (EUR) | E4: Ano | F4: % del Total
A5: FORMENTERA 12, JOAQUIN | B5: 4043 | C5: 20 | D5: =B5*C5 | E5: 2026 | F5: =D5/D30
A6: PLAZA CIRCULAR | B6: 1963 | C6: 20 | D6: =B6*C6 | E6: 2026 | F6: =D6/D30
A7: LA ALBERCA | B7: 1576 | C7: 20 | D7: =B7*C7 | E7: 2026 | F7: =D7/D30
A8: OBRA LUC2 | B8: 1049 | C8: 20 | D8: =B8*C8 | E8: 2026 | F8: =D8/D30
A9: A-13 | B9: 808 | C9: 20 | D9: =B9*C9 | E9: 2026 | F9: =D9/D30
A10: LA PARTE DIFICIL, ALICANTE | B10: 750 | C10: 20 | D10: =B10*C10 | E10: 2026 | F10: =D10/D30
A11: LA PARTE DIFICIL, MURCIA | B11: 51 | C11: 20 | D11: =B11*C11 | E11: 2026 | F11: =D11/D30
A12: CARTAGENA, MURCIA | B12: 630 | C12: 20 | D12: =B12*C12 | E12: 2026 | F12: =D12/D30
A13: FORMENTERA 14, JUANMA | B13: 643 | C13: 20 | D13: =B13*C13 | E13: 2026 | F13: =D13/D30
A14: BARINAS | B14: 537 | C14: 20 | D14: =B14*C14 | E14: 2026 | F14: =D14/D30
A15: CEMENTERIO, MURCIA | B15: 440 | C15: 20 | D15: =B15*C15 | E15: 2026 | F15: =D15/D30
A16: SANTA ROSA | B16: 437 | C16: 20 | D16: =B16*C16 | E16: 2026 | F16: =D16/D30
A17: CASTILLO DE ELDA | B17: 457 | C17: 20 | D17: =B17*C17 | E17: 2026 | F17: =D17/D30
A18: PEREAMAR | B18: 421 | C18: 20 | D18: =B18*C18 | E18: 2026 | F18: =D18/D30
A19: CBS | B19: 304 | C19: 20 | D19: =B19*C19 | E19: 2026 | F19: =D19/D30
A20: OBRA CARLA, PINOSO | B20: 221 | C20: 20 | D20: =B20*C20 | E20: 2026 | F20: =D20/D30
A21: GARAJE MURCIA | B21: 132 | C21: 20 | D21: =B21*C21 | E21: 2026 | F21: =D21/D30
A22: PISO IBI | B22: 117 | C22: 20 | D22: =B22*C22 | E22: 2026 | F22: =D22/D30
A23: OBRA PADRE TRINI | B23: 52 | C23: 20 | D23: =B23*C23 | E23: 2026 | F23: =D23/D30
A24: ALBERTO Y EVA | B24: 28 | C24: 20 | D24: =B24*C24 | E24: 2026 | F24: =D24/D30
A25: OBRA C/HUERTO CAPUCHINOS, MURCIA | B25: 24 | C25: 20 | D25: =B25*C25 | E25: 2026 | F25: =D25/D30
A26: FORMENTERA 14, JUANMA | B26: 3960 | C26: 20 | D26: =B26*C26 | E26: 2025 | F26: =D26/D30
A27: FORMENTERA 12, JOAQUIN | B27: 262 | C27: 20 | D27: =B27*C27 | E27: 2025 | F27: =D27/D30
A28: LA ALBERCA | B28: 273 | C28: 20 | D28: =B28*C28 | E28: 2025 | F28: =D28/D30
A29: BARINAS | B29: 138 | C29: 20 | D29: =B29*C29 | E29: 2025 | F29: =D29/D30
A30: TOTAL MANO DE OBRA | B30: =SUM(B5:B29) | D30: =SUM(D5:D29)

Sheet Gastos por Proyecto
A1: GASTOS DIRECTOS POR PROYECTO (del CSV de Holded)
A3: Proyecto | B3: Importe (EUR) | C3: Observaciones
A4: OBRA C/FORMENTERA, 12 (JOAQUIN) | B4: 292782.49
A5: OBRA C/FORMENTERA,14 ASPE (JUANMA) | B5: 276315.51
A6: OBRA C/IBIZA, ASPE (CASA CABO) | B6: 229026.91
A7: OBRA PLAZA CIRCULAR, MURCIA | B7: 188365.45
A8: LA ALBERCA (ADMINISTRACION) | B8: 56081.98
A9: OBRA LUC2 (ADMINISTRACION) | B9: 45321.16
A10: OBRA C/HUERTO CAPUCHINOS, MURCIA (COLEGIO MAYOR) | B10: 27881.98
A11: OBRA CEMENTERIO - PANTEON, MURCIA | B11: 23323.25
A12: PRESUPUESTO OBRA BARINAS - JUANPE Y TRINI (ADMINISTRACION) | B12: 18937.35
A13: OBRA MURO VECINO CAMPO | B13: 17027.34
A14: OBRA LA PARTE DIFICIL - EDIFICIO ALICANTE - C/MAESTRO BARBIERI | B14: 12724.51
A15: OBRAS MEJORA DEL VALLADO Y ENTORNO Y CENTRO DE RECEPCION DE VISITANTES DEL CASTILLO DE ELDA | B15: 11762.42
... A27: OBRA PADRE TRINI | B27: 298.32
A28: TOTAL GASTOS DIRECTOS | B28: =SUM(B4:B27)

Sheet Facturas por Obra
A1: FACTURAS POR OBRA - Todas las facturas directas (1052 facturas)
A2: Usa los filtros desplegables en la fila 3 para buscar por proyecto, proveedor, etc.
A3: Proyecto | B3: Codigo | C3: Fecha | D3: Titulo/Concepto | E3: Proveedor | F3: Estado | G3: Importe (EUR)
A4: 26002 - PRESUPUESTO OBRA GARAJE, MURCIA (LA PARTE DIFICIL) | B4: 1.173,00 | C4: 20/03/2026 | D4: INTALACIÓN COMPLETA DE ELECTRICIDAD EN GARAJE | E4: MOVE2GO SL. | F4: IMPUTADO | G4: 1087.5
A5: 26002 - PRESUPUESTO OBRA GARAJE, MURCIA (LA PARTE DIFICIL) | B5: 851,00 | C5: 23/02/2026 | D5: INTALACIÓN COMPLETA DE ELECTRICIDAD EN GARAJE | E5: MOVE2GO SL. | F5: IMPUTADO | G5: 1087.5
A6: 26002 - PRESUPUESTO OBRA GARAJE, MURCIA (LA PARTE DIFICIL) | B6: 874,00 | C6: 02/03/2026 | D6: LEROY MERLIN (PRESUPUESTO 603119) FOTO EN DOCUMENTOS | E6: LEROY MERLIN ESPAÑA SL | F6: IMPUTADO | G6: 469.96
A7: 26002 - PRESUPUESTO OBRA GARAJE, MURCIA (LA PARTE DIFICIL) | B7: 853,00 | C7: 23/02/2026 | D7: LEROY MERLIN (PRESUPUESTO 602161) FOTO EN DOCUMENTOS | E7: LEROY MERLIN ESPAÑA SL | F7: IMPUTADO | G7: 352.76
A8: 26002 - PRESUPUESTO OBRA GARAJE, MURCIA (LA PARTE DIFICIL) | B8: 852,00 | C8: 23/02/2026 | D8: LEROY MERLIN (DUPLICADO PRESUPUESTO 601689) FOTO EN DOCUMENTOS | E8: LEROY MERLIN ESPAÑA SL | F8: IMPUTADO | G8: 352.76
A9: ARREGLOS OBRAS ARAQUE Y MAQUEDA | B9: 820,00 | C9: 19/02/2026 | D9: ARREGLO ALMORADÍ | E9: GOCLIMA FRIO Y CALOR SL | F9: IMPUTADO | G9: 2150
A10: ARREGLOS OBRAS ARAQUE Y MAQUEDA | B10: 819,00 | C10: 19/02/2026 | D10: REPARACIÓN ALMORADÍ | F10: IMPUTADO | G10: 680
A11: ARREGLOS OBRAS ARAQUE Y MAQUEDA | B11: 1.409,00 | D11: NAYA ARQUITECTURA | E11: NAYA ARQUITECTURA Y DISEÑO GRAFICO SLP. | F11: SIN IMPUTAR | G11: 600
A12: ARREGLOS OBRAS ARAQUE Y MAQUEDA | B12: 1.408,00 | D12: PANEL CUBIERTA | E12: PANELES Y SISTEMAS DEL MEDITERRANEO SL. | F12: SIN IMPUTAR | G12: 464
A13: ARREGLOS OBRAS ARAQUE Y MAQUEDA | B13: 1.443,00 | C13: 05/05/2026 | D13: TOALLERO ELECTRICO | E13: SALTOKI ALICANTE SL. | F13: IMPUTADO | G13: 323.05
A14: ARREGLOS OBRAS ARAQUE Y MAQUEDA | B14: 821,00 | C14: 19/02/2026 | D14: ARREGLO ALMORADÍ | E14: GOCLIMA FRIO Y CALOR SL | F14: IMPUTADO | G14: 299
A15: ARREGLOS OBRAS ARAQUE Y MAQUEDA | B15: 1.418,00 | D15: TRABAJOS REALIZADOS | F15: SIN IMPUTAR | G15: 250
A16: ARREGLOS OBRAS ARAQUE Y MAQUEDA | B16: 1.445,00 | C16: 05/05/2026 | D16: CRISTALES | E16: ALEJANDRO CUTILLAS CAÑABATE | F16: IMPUTADO | G16: 186
A17: ARREGLOS OBRAS ARAQUE Y MAQUEDA | B17: 1.469,00 | C17: 05/05/2026 | D17: MATERIALES VARIOS | E17: SALTOKI ALICANTE SL. | F17: IMPUTADO | G17: 31.08
A18: ARREGLOS OBRAS ARAQUE Y MAQUEDA | B18: 1.474,00 | C18: 05/05/2026 | D18: MATERIAL VARIO | E18: FERRETERIA E INSTALACIONES AMOROS SL. | F18: IMPUTADO | G18: 1.69
A19: CARLOS Y ROCIO ESPINOSA | B19: 114,00 | D19: NAYA | F19: SIN IMPUTAR | G19: 600
A20: LA ALBERCA (ADMINISTRACION) | B20: 1.702,00 | C20: 16/06/2026 | D20: ELECTRICIDAD | F20: IMPUTADO | G20: 3444.02
A21: LA ALBERCA (ADMINISTRACION) | B21: 1.658,00 | C21: 04/06/2026 | D21: MATERIAL OBRA | E21: MATERIALES DE CONSTRUCCION EL CARACOLES SL | F21: IMPUTADO | G21: 3279.39
A22: LA ALBERCA (ADMINISTRACION) | B22: 1.174,00 | C22: 20/03/2026 | D22: PALA EXCAVADORA | E22: FRANCISO JAVIER SERNA GALVEZ | F22: IMPUTADO | G22: 3250
A23: LA ALBERCA (ADMINISTRACION) | B23: 536,00 | C23: 20/02/2026 | D23: PORTES LA ALBERCA | E23: FRANCISO JAVIER SERNA GALVEZ | F23: IMPUTADO | G23: 2980
A24: LA ALBERCA (ADMINISTRACION) | B24: 1.251,00 | C24: 15/04/2026 | D24: LLENADO LOSA #sotano | E24: GRUPO ALJEMA RELOSA SL. | F24: IMPUTADO | G24: 2772
A25: LA ALBERCA (ADMINISTRACION) | B25: 631,00 | C25: 20/02/2026 | D25: FERRALLA LOSA | E25: FERRALLAS MONFORTE DEL CID SL. | F25: IMPUTADO | G25: 2492.96
A26: LA ALBERCA (ADMINISTRACION) | B26: 1.521,00 | C26: 05/05/2026 | D26: GRESITE PISCINA Y MATERIAL | E26: MATERIALES DE CONSTRUCCION EL CARACOLES SL | F26: IMPUTADO | G26: 1633.85
A27: LA ALBERCA (ADMINISTRACION) | B27: 1.607,00 | C27: 21/05/2026 | D27: HORMIGON LOSA | E27: GRUPO ALJEMA RELOSA SL. | F27: IMPUTADO | G27: 1538.5
A28: LA ALBERCA (ADMINISTRACION) | B28: 1.522,00 | C28: 05/05/2026 | D28: PVC Y MATERIAL OBRA | E28: MATERIALES DE CONSTRUCCION EL CARACOLES SL | F28: IMPUTADO | G28: 1511.51
A29: LA ALBERCA (ADMINISTRACION) | B29: 1.560,00 | C29: 11/05/2026 | D29: HORMIGÓN FORJADO H25 Y BOMBA | E29: GRUPO ALJEMA RELOSA SL. | F29: IMPUTADO | G29: 1508.5
A30: LA ALBERCA (ADMINISTRACION) | B30: 1.635,00 | C30: 27/05/2026 | D30: FONTANERÍA | E30: FONTAFIX EAR | F30: IMPUTADO | G30: 1500
A31: LA ALBERCA (ADMINISTRACION) | B31: 1.589,00 | C31: 18/05/2026 | D31: PRESUPUESTO Nº 613558 | E31: LEROY MERLIN ESPAÑA SL | F31: IMPUTADO | G31: 1476.24
A32: LA ALBERCA (ADMINISTRACION) | B32: 1.632,00 | C32: 27/05/2026 | D32: PRESUPUESTO Nº 623752 | E32: LEROY MERLIN ESPAÑA SL | F32: IMPUTADO | G32: 1466.12
A33: LA ALBERCA (ADMINISTRACION) | B33: 1.550,00 | C33: 07/05/2026 | D33: PISCINA MURCIA | E33: FGC INSTALACIONES 2017, SOCIEDAD LIMITADA. | F33: IMPUTADO | G33: 1380.92
A34: LA ALBERCA (ADMINISTRACION) | B34: 1.162,00 | C34: 17/03/2026 | D34: INSTALACIONES 2017 SL | F34: IMPUTADO | G34: 1380.92
A35: LA ALBERCA (ADMINISTRACION) | B35: 1.483,00 | C35: 27/04/2026 | D35: HIERRO #forjado sótano | E35: FERRALLAS MONFORTE DEL CID SL. | F35: IMPUTADO | G35: 1216
A36: LA ALBERCA (ADMINISTRACION) | B36: 581,00 | C36: 20/02/2026 | D36: GUNITA PISCINA | F36: IMPUTADO | G36: 1196
A37: LA ALBERCA (ADMINISTRACION) | B37: 1.683,00 | C37: 09/06/2026 | D37: GRUA (TIRAR GRAVA) | E37: GRUAS Y MAQUINARIA PETREL SL | F37: IMPUTADO | G37: 1137.5
A38: LA ALBERCA (ADMINISTRACION) | B38: 1.161,00 | C38: 17/03/2026 | D38: FERRALLADO PISCINA | F38: IMPUTADO | G38: 1100
A39: LA ALBERCA (ADMINISTRACION) | B39: 1.160,00 | C39: 17/03/2026 | D39: GUNTIADO PISCINA | F39: IMPUTADO | G39: 1100
A40: LA ALBERCA (ADMINISTRACION) | B40: 579,00 | C40: 20/02/2026 | D40: Material Alberca | F40: IMPUTADO | G40: 1091.91
...

Sheet Prorrateo
A1: PRORRATEO DE GASTOS COMUNES
A3: Formula: (% Certificacion del proyecto / Total) x Total Gastos Comunes
A5: Proyecto | B5: Certificacion (EUR) | C5: % del Total | D5: Gasto Prorrateado (EUR)
A6: ='Certificaciones'!B4 | B6: ='Certificaciones'!C4 | C6: ='Certificaciones'!D4 | D6: =C6*'Resumen'!B7
A7: ='Certificaciones'!B5 | B7: ='Certificaciones'!C5 | C7: ='Certificaciones'!D5 | D7: =C7*'Resumen'!B7
A8: ='Certificaciones'!B6 | B8: ='Certificaciones'!C6 | C8: ='Certificaciones'!D6 | D8: =C8*'Resumen'!B7
A9: ='Certificaciones'!B7 | B9: ='Certificaciones'!C7 | C9: ='Certificaciones'!D7 | D9: =C9*'Resumen'!B7
A10: ='Certificaciones'!B8 | B10: ='Certificaciones'!C8 | C10: ='Certificaciones'!D8 | D10: =C10*'Resumen'!B7
A11: ='Certificaciones'!B9 | B11: ='Certificaciones'!C9 | C11: ='Certificaciones'!D9 | D11: =C11*'Resumen'!B7
A12: ='Certificaciones'!B10 | B12: ='Certificaciones'!C10 | C12: ='Certificaciones'!D10 | D12: =C12*'Resumen'!B7
A13: ='Certificaciones'!B11 | B13: ='Certificaciones'!C11 | C13: ='Certificaciones'!D11 | D13: =C13*'Resumen'!B7
A14: ='Certificaciones'!B12 | B14: ='Certificaciones'!C12 | C14: ='Certificaciones'!D12 | D14: =C14*'Resumen'!B7
A15: ='Certificaciones'!B13 | B15: ='Certificaciones'!C13 | C15: ='Certificaciones'!D13 | D15: =C15*'Resumen'!B7
A16: ='Certificaciones'!B14 | B16: ='Certificaciones'!C14 | C16: ='Certificaciones'!D14 | D16: =C16*'Resumen'!B7
A17: ='Certificaciones'!B15 | B17: ='Certificaciones'!C15 | C17: ='Certificaciones'!D15 | D17: =C17*'Resumen'!B7
A18: ='Certificaciones'!B16 | B18: ='Certificaciones'!C16 | C18: ='Certificaciones'!D16 | D18: =C18*'Resumen'!B7
A19: ='Certificaciones'!B17 | B19: ='Certificaciones'!C17 | C19: ='Certificaciones'!D17 | D19: =C19*'Resumen'!B7
A20: ='Certificaciones'!B18 | B20: ='Certificaciones'!C18 | C20: ='Certificaciones'!D18 | D20: =C20*'Resumen'!B7
A21: ='Certificaciones'!B19 | B21: ='Certificaciones'!C19 | C21: ='Certificaciones'!D19 | D21: =C21*'Resumen'!B7
A22: ='Certificaciones'!B20 | B22: ='Certificaciones'!C20 | C22: ='Certificaciones'!D20 | D22: =C22*'Resumen'!B7
A23: ='Certificaciones'!B21 | B23: ='Certificaciones'!C21 | C23: ='Certificaciones'!D21 | D23: =C23*'Resumen'!B7
A24: ='Certificaciones'!B22 | B24: ='Certificaciones'!C22 | C24: ='Certificaciones'!D22 | D24: =C24*'Resumen'!B7
A25: ='Certificaciones'!B23 | B25: ='Certificaciones'!C23 | C25: ='Certificaciones'!D23 | D25: =C25*'Resumen'!B7
A26: TOTAL | B26: =SUM(B6:B25) | C26: =SUM(C6:C25) | D26: =SUM(D6:D25)
